<?xml version="1.0" ?>
<!--
  daro.sdf — Gazebo Harmonic model for DARO robot

  Matches real robot geometry from robot_config.h / daro_min.urdf:
    body:             241.3mm x 76.2mm x 50.8mm
    wheel_radius:     30mm
    wheel_separation: 160mm
    lidar offset:     +80mm forward, +100mm up from base_link

  Plugins:
    DiffDrive  — subscribes /cmd_vel, publishes /odom + TF odom->base_link
    LidarSensor — publishes /scan (same topic as real sllidar_node)
-->
<sdf version="1.8">
  <model name="daro">
    <pose>0 0 0 0 0 0</pose>

    <!-- ── Chassis ─────────────────────────────────────────────────────── -->
    <link name="base_link">
      <inertial>
        <mass>1.5</mass>
        <inertia>
          <!-- box inertia: m/12*(y²+z²), m/12*(x²+z²), m/12*(x²+y²) -->
          <ixx>0.00327</ixx>
          <iyy>0.01023</iyy>
          <izz>0.01202</izz>
          <ixy>0</ixy><ixz>0</ixz><iyz>0</iyz>
        </inertia>
      </inertial>

      <visual name="chassis_visual">
        <pose>0 0 0.055 0 0 0</pose>
        <geometry>
          <box><size>0.2413 0.0762 0.0508</size></box>
        </geometry>
        <material>
          <ambient>0.2 0.2 0.8 1</ambient>
          <diffuse>0.2 0.2 0.8 1</diffuse>
        </material>
      </visual>

      <collision name="chassis_collision">
        <pose>0 0 0.055 0 0 0</pose>
        <geometry>
          <box><size>0.2413 0.0762 0.0508</size></box>
        </geometry>
      </collision>
    </link>

    <!-- ── Left wheel ─────────────────────────────────────────────────── -->
    <link name="left_wheel">
      <pose>0 0.08 0.03 1.5707963 0 0</pose>
      <inertial>
        <mass>0.1</mass>
        <inertia>
          <ixx>0.0000453</ixx><iyy>0.0000453</iyy><izz>0.000045</izz>
          <ixy>0</ixy><ixz>0</ixz><iyz>0</iyz>
        </inertia>
      </inertial>
      <visual name="visual">
        <geometry>
          <cylinder><radius>0.03</radius><length>0.025</length></cylinder>
        </geometry>
        <material>
          <ambient>0.1 0.1 0.1 1</ambient>
          <diffuse>0.2 0.2 0.2 1</diffuse>
        </material>
      </visual>
      <collision name="collision">
        <geometry>
          <cylinder><radius>0.03</radius><length>0.025</length></cylinder>
        </geometry>
        <surface>
          <friction><ode><mu>1.0</mu><mu2>1.0</mu2></ode></friction>
        </surface>
      </collision>
    </link>

    <joint name="left_wheel_joint" type="revolute">
      <parent>base_link</parent>
      <child>left_wheel</child>
      <axis>
        <xyz>0 0 1</xyz>
        <limit><lower>-1e+16</lower><upper>1e+16</upper></limit>
      </axis>
    </joint>

    <!-- ── Right wheel ────────────────────────────────────────────────── -->
    <link name="right_wheel">
      <pose>0 -0.08 0.03 1.5707963 0 0</pose>
      <inertial>
        <mass>0.1</mass>
        <inertia>
          <ixx>0.0000453</ixx><iyy>0.0000453</iyy><izz>0.000045</izz>
          <ixy>0</ixy><ixz>0</ixz><iyz>0</iyz>
        </inertia>
      </inertial>
      <visual name="visual">
        <geometry>
          <cylinder><radius>0.03</radius><length>0.025</length></cylinder>
        </geometry>
        <material>
          <ambient>0.1 0.1 0.1 1</ambient>
          <diffuse>0.2 0.2 0.2 1</diffuse>
        </material>
      </visual>
      <collision name="collision">
        <geometry>
          <cylinder><radius>0.03</radius><length>0.025</length></cylinder>
        </geometry>
        <surface>
          <friction><ode><mu>1.0</mu><mu2>1.0</mu2></ode></friction>
        </surface>
      </collision>
    </link>

    <joint name="right_wheel_joint" type="revolute">
      <parent>base_link</parent>
      <child>right_wheel</child>
      <axis>
        <xyz>0 0 1</xyz>
        <limit><lower>-1e+16</lower><upper>1e+16</upper></limit>
      </axis>
    </joint>

    <!-- ── Front caster (ball) ────────────────────────────────────────── -->
    <link name="caster">
      <pose>0.09 0 0.01 0 0 0</pose>
      <inertial>
        <mass>0.05</mass>
        <inertia>
          <ixx>0.000002</ixx><iyy>0.000002</iyy><izz>0.000002</izz>
          <ixy>0</ixy><ixz>0</ixz><iyz>0</iyz>
        </inertia>
      </inertial>
      <visual name="visual">
        <geometry><sphere><radius>0.01</radius></sphere></geometry>
        <material><ambient>0.5 0.5 0.5 1</ambient></material>
      </visual>
      <collision name="collision">
        <geometry><sphere><radius>0.01</radius></sphere></geometry>
        <surface>
          <friction><ode><mu>0.0</mu><mu2>0.0</mu2></ode></friction>
        </surface>
      </collision>
    </link>

    <joint name="caster_joint" type="fixed">
      <parent>base_link</parent>
      <child>caster</child>
    </joint>

    <!-- ── LiDAR ──────────────────────────────────────────────────────── -->
    <link name="laser">
      <pose>0.08 0 0.10 0 0 0</pose>
      <inertial>
        <mass>0.05</mass>
        <inertia>
          <ixx>0.000001</ixx><iyy>0.000001</iyy><izz>0.000001</izz>
          <ixy>0</ixy><ixz>0</ixz><iyz>0</iyz>
        </inertia>
      </inertial>

      <visual name="visual">
        <geometry><cylinder><radius>0.035</radius><length>0.04</length></cylinder></geometry>
        <material><ambient>0.1 0.1 0.1 1</ambient></material>
      </visual>

      <sensor name="lidar_sensor" type="lidar">
        <always_on>true</always_on>
        <update_rate>10</update_rate>
        <visualize>true</visualize>
        <topic>/scan</topic>
        <lidar>
          <scan>
            <horizontal>
              <samples>360</samples>
              <resolution>1</resolution>
              <min_angle>-3.14159</min_angle>
              <max_angle>3.14159</max_angle>
            </horizontal>
          </scan>
          <range>
            <min>0.15</min>
            <max>12.0</max>
            <resolution>0.01</resolution>
          </range>
          <noise>
            <type>gaussian</type>
            <mean>0.0</mean>
            <stddev>0.01</stddev>
          </noise>
        </lidar>
      </sensor>
    </link>

    <joint name="laser_joint" type="fixed">
      <parent>base_link</parent>
      <child>laser</child>
    </joint>

    <!-- ── Differential drive plugin ─────────────────────────────────── -->
    <plugin filename="gz-sim-diff-drive-system"
            name="gz::sim::systems::DiffDrive">
      <left_joint>left_wheel_joint</left_joint>
      <right_joint>right_wheel_joint</right_joint>
      <wheel_separation>0.16</wheel_separation>
      <wheel_radius>0.03</wheel_radius>
      <odom_publish_frequency>20</odom_publish_frequency>
      <topic>/cmd_vel</topic>
      <odom_topic>/odom</odom_topic>
      <tf_topic>/tf</tf_topic>
      <frame_id>odom</frame_id>
      <child_frame_id>base_link</child_frame_id>
      <max_linear_acceleration>2</max_linear_acceleration>
    </plugin>

    <!-- ── Joint state publisher ──────────────────────────────────────── -->
    <plugin filename="gz-sim-joint-state-publisher-system"
            name="gz::sim::systems::JointStatePublisher">
      <topic>/joint_states</topic>
    </plugin>

  </model>
</sdf>
